Workbook

Sheet Início
A1: ÍNDICE SPAMIREZA — COMO USAR
A3: 1. Config | B3: Ajuste os pesos, o multiplicador de cada liga e diga em qual liga cada clã está nesta temporada.
A4: 2. Jogadores | B4: Liste cada jogador uma vez: nome, clã (1 a 5) e nível de TH.
A5: 3. Dados | B5: Uma linha por jogador por guerra (7 guerras). Preencha estrelas só se atacou; deixe em branco se não atacou.
A6: → Substituído | B6: Se o jogador foi TIRADO da line antes de atacar, marque 'Substituído = S'. Isso NÃO conta contra ele.
A7: → Faltou | B7: Se ficou escalado e simplesmente não usou o ataque, deixe 'Substituído = N' e estrelas em branco. Isso DERRUBA a confiabilidade.
A8: 4. Ranking Geral | B8: Calcula sozinho: Índice ajustado (decide subir/descer), MVP e zonas de promoção/rebaixamento por clã.
A9: Como pontua | B9: Índice = 55% ataque (★/ataque) + 20% defesa + 25% confiabilidade, multiplicado pela dificuldade da liga.
A10: MVP | B10: Maior (estrelas de ataque + estrelas negadas na defesa) na liga atual.
A11: Adicionar jogador | B11: Insira a linha em 'Jogadores' e copie uma linha inteira do 'Ranking Geral' para baixo — as fórmulas se ajustam.

Sheet Config
A1: CONFIGURAÇÃO — ÍNDICE SPAMIREZA
A3: PESOS DO ÍNDICE
A4: Peso Ataque | B4: 0.55
A5: Peso Defesa | B5: 0.2
A6: Peso Confiabilidade | B6: 0.25
A7: Piso de ataques (elegibilidade) | B7: 3
A8: Nº promovidos/rebaixados por clã | B8: 2
A10: MULTIPLICADOR DE LIGA
A11: Liga | B11: Multiplicador
A12: Champion I | B12: 1
A13: Champion II | B13: 0.98
A14: Champion III | B14: 0.96
A15: Master I | B15: 0.93
A16: Master II | B16: 0.9
A17: Master III | B17: 0.87
A18: Crystal I | B18: 0.83
A19: Crystal II | B19: 0.8
A20: Crystal III | B20: 0.77
A21: Gold I | B21: 0.72
A22: Gold II | B22: 0.69
A23: Gold III | B23: 0.66
A24: Prata ou abaixo | B24: 0.6
A27: CLÃS DESTA TEMPORADA
A28: Clã | B28: Nome | C28: Liga atual
A29: 1 | B29: SpamiReza | C29: Champion I
A30: 2 | B30: RezaSpamandu | C30: Champion III
A31: 3 | B31: ScamiReza | C31: Master I
A32: 4 | B32: RezaScamandu | C32: Master III
A33: 5 | B33: e-SpamiReza | C33: Crystal I

Sheet Jogadores
A1: JOGADORES
A2: Jogador | B2: Clã (1-5) | C2: TH
A3: Lippe | B3: 1 | C3: 16
A4: Bruno | B4: 1 | C4: 16
A5: Kaio | B5: 1 | C5: 15
A6: Duda | B6: 1 | C6: 16
A7: Titi | B7: 1 | C7: 15
A8: Renan | B8: 2 | C8: 15
A9: Gustavo | B9: 2 | C9: 15
A10: Léo | B10: 2 | C10: 14
A11: Mari | B11: 2 | C11: 15
A12: Zé | B12: 2 | C12: 14
A13: Pedro | B13: 3 | C13: 14
A14: Nanda | B14: 3 | C14: 14
... A27: Nino | B27: 5 | C27: 11

Sheet Dados
A1: DADOS DA LIGA — 1 linha por jogador por guerra
A2: Jogador | B2: Guerra | C2: Escalado (S/N) | D2: Substituído antes de atacar (S/N) | E2: Estrelas (0-3) | F2: Destruição % | G2: Nº Defesas | H2: Estrelas sofridas | I2: Destruição sofrida %
A3: Lippe | B3: 1 | C3: S | D3: N | E3: 3 | F3: 97 | G3: 1 | H3: 1 | I3: 83
A4: Lippe | B4: 2 | C4: S | D4: N | E4: 3 | F4: 96 | G4: 1 | H4: 0 | I4: 54
A5: Lippe | B5: 3 | C5: S | D5: N | E5: 3 | F5: 100 | G5: 2 | H5: 0 | I5: 91
A6: Lippe | B6: 4 | C6: S | D6: N | E6: 3 | F6: 99 | G6: 2 | H6: 0 | I6: 88
A7: Lippe | B7: 5 | C7: S | D7: N | E7: 3 | F7: 98 | G7: 2 | H7: 2 | I7: 74
A8: Lippe | B8: 6 | C8: S | D8: N | E8: 3 | F8: 98 | G8: 2 | H8: 1 | I8: 42
A9: Lippe | B9: 7 | C9: S | D9: N | E9: 2 | F9: 87 | G9: 1 | H9: 0 | I9: 69
A10: Bruno | B10: 1 | C10: S | D10: N | E10: 3 | F10: 97 | G10: 2 | H10: 2 | I10: 44
A11: Bruno | B11: 2 | C11: S | D11: N | E11: 3 | F11: 97 | G11: 2 | H11: 2 | I11: 80
A12: Bruno | B12: 3 | C12: S | D12: N | E12: 3 | F12: 96 | G12: 1 | H12: 1 | I12: 91
A13: Bruno | B13: 4 | C13: S | D13: N | E13: 3 | F13: 100 | G13: 2 | H13: 0 | I13: 81
A14: Bruno | B14: 5 | C14: S | D14: N | E14: 3 | F14: 100 | G14: 2 | H14: 1 | I14: 77
... A20: Kaio | B20: 4 | C20: S | D20: N | E20: 3 | F20: 98 | G20: 1 | H20: 0 | I20: 89
A21: Kaio | B21: 5 | C21: S | D21: N | G21: 2 | H21: 0 | I21: 63
A22: Kaio | B22: 6 | C22: S | D22: N | E22: 3 | F22: 96 | G22: 1 | H22: 1 | I22: 45
A23: Kaio | B23: 7 | C23: S | D23: N | E23: 3 | F23: 100 | G23: 1 | H23: 0 | I23: 70
A24: Duda | B24: 1 | C24: S | D24: N | E24: 3 | F24: 100 | G24: 2 | H24: 4 | I24: 88
A25: Duda | B25: 2 | C25: S | D25: N | E25: 3 | F25: 98 | G25: 2 | H25: 2 | I25: 55
A26: Duda | B26: 3 | C26: S | D26: N | E26: 3 | F26: 97 | G26: 1 | H26: 0 | I26: 85
A27: Duda | B27: 4 | C27: S | D27: N | E27: 2 | F27: 90 | G27: 1 | H27: 1 | I27: 57
A28: Duda | B28: 5 | C28: S | D28: N | E28: 3 | F28: 100 | G28: 2 | H28: 0 | I28: 66
A29: Duda | B29: 6 | C29: S | D29: N | E29: 3 | F29: 99 | G29: 2 | H29: 1 | I29: 83
A30: Duda | B30: 7 | C30: S | D30: N | E30: 3 | F30: 98 | G30: 1 | H30: 0 | I30: 52
A31: Titi | B31: 1 | C31: S | D31: N | E31: 3 | F31: 96 | G31: 2 | H31: 4 | I31: 46
A32: Titi | B32: 2 | C32: S | D32: N | G32: 1 | H32: 2 | I32: 94
A33: Titi | B33: 3 | C33: S | D33: N | E33: 2 | F33: 81 | G33: 1 | H33: 0 | I33: 64
A34: Titi | B34: 4 | C34: S | D34: N | E34: 3 | F34: 100 | G34: 2 | H34: 0 | I34: 43
A35: Titi | B35: 5 | C35: S | D35: N | G35: 1 | H35: 0 | I35: 70
A36: Titi | B36: 6 | C36: S | D36: N | E36: 1 | F36: 57 | G36: 1 | H36: 0 | I36: 44
A37: Titi | B37: 7 | C37: S | D37: N | E37: 1 | F37: 62 | G37: 1 | H37: 1 | I37: 66
A38: Renan | B38: 1 | C38: S | D38: N | E38: 3 | F38: 98 | G38: 1 | H38: 1 | I38: 60
A39: Renan | B39: 2 | C39: S | D39: N | E39: 3 | F39: 98 | G39: 2 | H39: 1 | I39: 44
A40: Renan | B40: 3 | C40: S | D40: N | E40: 3 | F40: 96 | G40: 1 | H40: 0 | I40: 72
A41: Renan | B41: 4 | C41: S | D41: N | E41: 2 | F41: 87 | G41: 2 | H41: 0 | I41: 74
A42: Renan | B42: 5 | C42: S | D42: N | E42: 2 | F42: 96 | G42: 1 | H42: 1 | I42: 75
A43: Renan | B43: 6 | C43: S | D43: N | E43: 2 | F43: 84 | G43: 2 | H43: 0 | I43: 75
A44: Renan | B44: 7 | C44: S | D44: N | E44: 3 | F44: 98 | G44: 1 | H44: 1 | I44: 94
A45: Gustavo | B45: 1 | C45: S | D45: N | E45: 2 | F45: 81 | G45: 1 | H45: 1 | I45: 93
...

Sheet Ranking Geral
A1: RANKING GERAL — ÍNDICE SPAMIREZA
A2: Jogador | B2: Clã | C2: Clã (nome) | D2: Liga | E2: TH | F2: Ataques | G2: Total ★ | H2: ★/ataque | I2: Destr. média % | J2: Oportun. | K2: Confiab. % | L2: Total def. | M2: ★ sofridas | N2: ★ sofr./def | O2: Nota Ataque | P2: Nota Defesa | Q2: Nota Confiab | R2: Índice bruto | S2: Multipl. | T2: ÍNDICE AJUST. | U2: MVP score | V2: Rank clã | W2: Zona
A3: =Jogadores!A3 -> Lippe | B3: =IFERROR(VLOOKUP($A3,Jogadores!$A$3:$C$120,2,FALSE()),"") -> 1 | C3: =IFERROR(VLOOKUP($B3,Config!$A$29:$C$33,2,FALSE()),"") -> SpamiReza | D3: =IFERROR(VLOOKUP($B3,Config!$A$29:$C$33,3,FALSE()),"") -> Champion I | E3: =IFERROR(VLOOKUP($A3,Jogadores!$A$3:$C$120,3,FALSE()),"") -> 16 | F3: =COUNTIFS(Dados!$A$3:$A$177,$A3,Dados!$E$3:$E$177,">=0") -> 7 | G3: =SUMIFS(Dados!$E$3:$E$177,Dados!$A$3:$A$177,$A3) -> 20 | H3: =IFERROR(G3/F3,0) -> 2.8571429 | I3: =IFERROR(AVERAGEIFS(Dados!$F$3:$F$177,Dados!$A$3:$A$177,$A3,Dados!$E$3:$E$177,">=0"),0) -> 96.428571 | J3: =COUNTIFS(Dados!$A$3:$A$177,$A3,Dados!$C$3:$C$177,"S",Dados!$D$3:$D$177,"N") -> 7 | K3: =IFERROR(MIN(1,F3/J3),0) -> 1 | L3: =SUMIFS(Dados!$G$3:$G$177,Dados!$A$3:$A$177,$A3) -> 11 | M3: =SUMIFS(Dados!$H$3:$H$177,Dados!$A$3:$A$177,$A3) -> 4 | N3: =IFERROR(M3/L3,0) -> 0.36363636 | O3: =H3/3*100 -> 95.238095 | P3: =IF(L3=0,100,(1-M3/(3*L3))*100) -> 87.878788 | Q3: =K3*100 -> 100 | R3: =Config!$B$4*O3+Config!$B$5*P3+Config!$B$6*Q3 -> 94.95671 | S3: =IFERROR(VLOOKUP($D3,Config!$A$12:$B$24,2,FALSE()),1) -> 1 | T3: =R3*S3 -> 94.95671 | U3: =G3+(3*L3-M3) -> 49 | V3: =IF($A3="","",SUMPRODUCT(($B$3:$B$27=$B3)*($T$3:$T$27>$T3))+1) -> 1 | W3: =IF($A3="","",IF($F3<Config!$B$7,"Sem amostra",IF(AND($B3>1,$V3<=Config!$B$8),"⬆ Promoção",IF(AND($B3<5,$V3>COUNTIF($B$3:$B$27,$B3)-Config!$B$8),"⬇ Rebaixamento","—")))) -> —
A4: =Jogadores!A4 -> Bruno | B4: =IFERROR(VLOOKUP($A4,Jogadores!$A$3:$C$120,2,FALSE()),"") -> 1 | C4: =IFERROR(VLOOKUP($B4,Config!$A$29:$C$33,2,FALSE()),"") -> SpamiReza | D4: =IFERROR(VLOOKUP($B4,Config!$A$29:$C$33,3,FALSE()),"") -> Champion I | E4: =IFERROR(VLOOKUP($A4,Jogadores!$A$3:$C$120,3,FALSE()),"") -> 16 | F4: =COUNTIFS(Dados!$A$3:$A$177,$A4,Dados!$E$3:$E$177,">=0") -> 7 | G4: =SUMIFS(Dados!$E$3:$E$177,Dados!$A$3:$A$177,$A4) -> 20 | H4: =IFERROR(G4/F4,0) -> 2.8571429 | I4: =IFERROR(AVERAGEIFS(Dados!$F$3:$F$177,Dados!$A$3:$A$177,$A4,Dados!$E$3:$E$177,">=0"),0) -> 98 | J4: =COUNTIFS(Dados!$A$3:$A$177,$A4,Dados!$C$3:$C$177,"S",Dados!$D$3:$D$177,"N") -> 7 | K4: =IFERROR(MIN(1,F4/J4),0) -> 1 | L4: =SUMIFS(Dados!$G$3:$G$177,Dados!$A$3:$A$177,$A4) -> 12 | M4: =SUMIFS(Dados!$H$3:$H$177,Dados!$A$3:$A$177,$A4) -> 6 | N4: =IFERROR(M4/L4,0) -> 0.5 | O4: =H4/3*100 -> 95.238095 | P4: =IF(L4=0,100,(1-M4/(3*L4))*100) -> 83.333333 | Q4: =K4*100 -> 100 | R4: =Config!$B$4*O4+Config!$B$5*P4+Config!$B$6*Q4 -> 94.047619 | S4: =IFERROR(VLOOKUP($D4,Config!$A$12:$B$24,2,FALSE()),1) -> 1 | T4: =R4*S4 -> 94.047619 | U4: =G4+(3*L4-M4) -> 50 | V4: =IF($A4="","",SUMPRODUCT(($B$3:$B$27=$B4)*($T$3:$T$27>$T4))+1) -> 2 | W4: =IF($A4="","",IF($F4<Config!$B$7,"Sem amostra",IF(AND($B4>1,$V4<=Config!$B$8),"⬆ Promoção",IF(AND($B4<5,$V4>COUNTIF($B$3:$B$27,$B4)-Config!$B$8),"⬇ Rebaixamento","—")))) -> —
A5: =Jogadores!A5 -> Kaio | B5: =IFERROR(VLOOKUP($A5,Jogadores!$A$3:$C$120,2,FALSE()),"") -> 1 | C5: =IFERROR(VLOOKUP($B5,Config!$A$29:$C$33,2,FALSE()),"") -> SpamiReza | D5: =IFERROR(VLOOKUP($B5,Config!$A$29:$C$33,3,FALSE()),"") -> Champion I | E5: =IFERROR(VLOOKUP($A5,Jogadores!$A$3:$C$120,3,FALSE()),"") -> 15 | F5: =COUNTIFS(Dados!$A$3:$A$177,$A5,Dados!$E$3:$E$177,">=0") -> 6 | G5: =SUMIFS(Dados!$E$3:$E$177,Dados!$A$3:$A$177,$A5) -> 17 | H5: =IFERROR(G5/F5,0) -> 2.8333333 | I5: =IFERROR(AVERAGEIFS(Dados!$F$3:$F$177,Dados!$A$3:$A$177,$A5,Dados!$E$3:$E$177,">=0"),0) -> 94.833333 | J5: =COUNTIFS(Dados!$A$3:$A$177,$A5,Dados!$C$3:$C$177,"S",Dados!$D$3:$D$177,"N") -> 7 | K5: =IFERROR(MIN(1,F5/J5),0) -> 0.85714286 | L5: =SUMIFS(Dados!$G$3:$G$177,Dados!$A$3:$A$177,$A5) -> 9 | M5: =SUMIFS(Dados!$H$3:$H$177,Dados!$A$3:$A$177,$A5) -> 3 | N5: =IFERROR(M5/L5,0) -> 0.33333333 | O5: =H5/3*100 -> 94.444444 | P5: =IF(L5=0,100,(1-M5/(3*L5))*100) -> 88.888889 | Q5: =K5*100 -> 85.714286 | R5: =Config!$B$4*O5+Config!$B$5*P5+Config!$B$6*Q5 -> 91.150794 | S5: =IFERROR(VLOOKUP($D5,Config!$A$12:$B$24,2,FALSE()),1) -> 1 | T5: =R5*S5 -> 91.150794 | U5: =G5+(3*L5-M5) -> 41 | V5: =IF($A5="","",SUMPRODUCT(($B$3:$B$27=$B5)*($T$3:$T$27>$T5))+1) -> 4 | W5: =IF($A5="","",IF($F5<Config!$B$7,"Sem amostra",IF(AND($B5>1,$V5<=Config!$B$8),"⬆ Promoção",IF(AND($B5<5,$V5>COUNTIF($B$3:$B$27,$B5)-Config!$B$8),"⬇ Rebaixamento","—")))) -> ⬇ Rebaixamento
A6: =Jogadores!A6 -> Duda | B6: =IFERROR(VLOOKUP($A6,Jogadores!$A$3:$C$120,2,FALSE()),"") -> 1 | C6: =IFERROR(VLOOKUP($B6,Config!$A$29:$C$33,2,FALSE()),"") -> SpamiReza | D6: =IFERROR(VLOOKUP($B6,Config!$A$29:$C$33,3,FALSE()),"") -> Champion I | E6: =IFERROR(VLOOKUP($A6,Jogadores!$A$3:$C$120,3,FALSE()),"") -> 16 | F6: =COUNTIFS(Dados!$A$3:$A$177,$A6,Dados!$E$3:$E$177,">=0") -> 7 | G6: =SUMIFS(Dados!$E$3:$E$177,Dados!$A$3:$A$177,$A6) -> 20 | H6: =IFERROR(G6/F6,0) -> 2.8571429 | I6: =IFERROR(AVERAGEIFS(Dados!$F$3:$F$177,Dados!$A$3:$A$177,$A6,Dados!$E$3:$E$177,">=0"),0) -> 97.428571 | J6: =COUNTIFS(Dados!$A$3:$A$177,$A6,Dados!$C$3:$C$177,"S",Dados!$D$3:$D$177,"N") -> 7 | K6: =IFERROR(MIN(1,F6/J6),0) -> 1 | L6: =SUMIFS(Dados!$G$3:$G$177,Dados!$A$3:$A$177,$A6) -> 11 | M6: =SUMIFS(Dados!$H$3:$H$177,Dados!$A$3:$A$177,$A6) -> 8 | N6: =IFERROR(M6/L6,0) -> 0.72727273 | O6: =H6/3*100 -> 95.238095 | P6: =IF(L6=0,100,(1-M6/(3*L6))*100) -> 75.757576 | Q6: =K6*100 -> 100 | R6: =Config!$B$4*O6+Config!$B$5*P6+Config!$B$6*Q6 -> 92.532468 | S6: =IFERROR(VLOOKUP($D6,Config!$A$12:$B$24,2,FALSE()),1) -> 1 | T6: =R6*S6 -> 92.532468 | U6: =G6+(3*L6-M6) -> 45 | V6: =IF($A6="","",SUMPRODUCT(($B$3:$B$27=$B6)*($T$3:$T$27>$T6))+1) -> 3 | W6: =IF($A6="","",IF($F6<Config!$B$7,"Sem amostra",IF(AND($B6>1,$V6<=Config!$B$8),"⬆ Promoção",IF(AND($B6<5,$V6>COUNTIF($B$3:$B$27,$B6)-Config!$B$8),"⬇ Rebaixamento","—")))) -> —
A7: =Jogadores!A7 -> Titi | B7: =IFERROR(VLOOKUP($A7,Jogadores!$A$3:$C$120,2,FALSE()),"") -> 1 | C7: =IFERROR(VLOOKUP($B7,Config!$A$29:$C$33,2,FALSE()),"") -> SpamiReza | D7: =IFERROR(VLOOKUP($B7,Config!$A$29:$C$33,3,FALSE()),"") -> Champion I | E7: =IFERROR(VLOOKUP($A7,Jogadores!$A$3:$C$120,3,FALSE()),"") -> 15 | F7: =COUNTIFS(Dados!$A$3:$A$177,$A7,Dados!$E$3:$E$177,">=0") -> 5 | G7: =SUMIFS(Dados!$E$3:$E$177,Dados!$A$3:$A$177,$A7) -> 10 | H7: =IFERROR(G7/F7,0) -> 2 | I7: =IFERROR(AVERAGEIFS(Dados!$F$3:$F$177,Dados!$A$3:$A$177,$A7,Dados!$E$3:$E$177,">=0"),0) -> 79.2 | J7: =COUNTIFS(Dados!$A$3:$A$177,$A7,Dados!$C$3:$C$177,"S",Dados!$D$3:$D$177,"N") -> 7 | K7: =IFERROR(MIN(1,F7/J7),0) -> 0.71428571 | L7: =SUMIFS(Dados!$G$3:$G$177,Dados!$A$3:$A$177,$A7) -> 9 | M7: =SUMIFS(Dados!$H$3:$H$177,Dados!$A$3:$A$177,$A7) -> 7 | N7: =IFERROR(M7/L7,0) -> 0.77777778 | O7: =H7/3*100 -> 66.666667 | P7: =IF(L7=0,100,(1-M7/(3*L7))*100) -> 74.074074 | Q7: =K7*100 -> 71.428571 | R7: =Config!$B$4*O7+Config!$B$5*P7+Config!$B$6*Q7 -> 69.338624 | S7: =IFERROR(VLOOKUP($D7,Config!$A$12:$B$24,2,FALSE()),1) -> 1 | T7: =R7*S7 -> 69.338624 | U7: =G7+(3*L7-M7) -> 30 | V7: =IF($A7="","",SUMPRODUCT(($B$3:$B$27=$B7)*($T$3:$T$27>$T7))+1) -> 5 | W7: =IF($A7="","",IF($F7<Config!$B$7,"Sem amostra",IF(AND($B7>1,$V7<=Config!$B$8),"⬆ Promoção",IF(AND($B7<5,$V7>COUNTIF($B$3:$B$27,$B7)-Config!$B$8),"⬇ Rebaixamento","—")))) -> ⬇ Rebaixamento
A8: =Jogadores!A8 -> Renan | B8: =IFERROR(VLOOKUP($A8,Jogadores!$A$3:$C$120,2,FALSE()),"") -> 2 | C8: =IFERROR(VLOOKUP($B8,Config!$A$29:$C$33,2,FALSE()),"") -> RezaSpamandu | D8: =IFERROR(VLOOKUP($B8,Config!$A$29:$C$33,3,FALSE()),"") -> Champion III | E8: =IFERROR(VLOOKUP($A8,Jogadores!$A$3:$C$120,3,FALSE()),"") -> 15 | F8: =COUNTIFS(Dados!$A$3:$A$177,$A8,Dados!$E$3:$E$177,">=0") -> 7 | G8: =SUMIFS(Dados!$E$3:$E$177,Dados!$A$3:$A$177,$A8) -> 18 | H8: =IFERROR(G8/F8,0) -> 2.5714286 | I8: =IFERROR(AVERAGEIFS(Dados!$F$3:$F$177,Dados!$A$3:$A$177,$A8,Dados!$E$3:$E$177,">=0"),0) -> 93.857143 | J8: =COUNTIFS(Dados!$A$3:$A$177,$A8,Dados!$C$3:$C$177,"S",Dados!$D$3:$D$177,"N") -> 7 | K8: =IFERROR(MIN(1,F8/J8),0) -> 1 | L8: =SUMIFS(Dados!$G$3:$G$177,Dados!$A$3:$A$177,$A8) -> 10 | M8: =SUMIFS(Dados!$H$3:$H$177,Dados!$A$3:$A$177,$A8) -> 4 | N8: =IFERROR(M8/L8,0) -> 0.4 | O8: =H8/3*100 -> 85.714286 | P8: =IF(L8=0,100,(1-M8/(3*L8))*100) -> 86.666667 | Q8: =K8*100 -> 100 | R8: =Config!$B$4*O8+Config!$B$5*P8+Config!$B$6*Q8 -> 89.47619 | S8: =IFERROR(VLOOKUP($D8,Config!$A$12:$B$24,2,FALSE()),1) -> 0.96 | T8: =R8*S8 -> 85.897143 | U8: =G8+(3*L8-M8) -> 44 | V8: =IF($A8="","",SUMPRODUCT(($B$3:$B$27=$B8)*($T$3:$T$27>$T8))+1) -> 2 | W8: =IF($A8="","",IF($F8<Config!$B$7,"Sem amostra",IF(AND($B8>1,$V8<=Config!$B$8),"⬆ Promoção",IF(AND($B8<5,$V8>COUNTIF($B$3:$B$27,$B8)-Config!$B$8),"⬇ Rebaixamento","—")))) -> ⬆ Promoção
A9: =Jogadores!A9 -> Gustavo | B9: =IFERROR(VLOOKUP($A9,Jogadores!$A$3:$C$120,2,FALSE()),"") -> 2 | C9: =IFERROR(VLOOKUP($B9,Config!$A$29:$C$33,2,FALSE()),"") -> RezaSpamandu | D9: =IFERROR(VLOOKUP($B9,Config!$A$29:$C$33,3,FALSE()),"") -> Champion III | E9: =IFERROR(VLOOKUP($A9,Jogadores!$A$3:$C$120,3,FALSE()),"") -> 15 | F9: =COUNTIFS(Dados!$A$3:$A$177,$A9,Dados!$E$3:$E$177,">=0") -> 5 | G9: =SUMIFS(Dados!$E$3:$E$177,Dados!$A$3:$A$177,$A9) -> 13 | H9: =IFERROR(G9/F9,0) -> 2.6 | I9: =IFERROR(AVERAGEIFS(Dados!$F$3:$F$177,Dados!$A$3:$A$177,$A9,Dados!$E$3:$E$177,">=0"),0) -> 92.8 | J9: =COUNTIFS(Dados!$A$3:$A$177,$A9,Dados!$C$3:$C$177,"S",Dados!$D$3:$D$177,"N") -> 7 | K9: =IFERROR(MIN(1,F9/J9),0) -> 0.71428571 | L9: =SUMIFS(Dados!$G$3:$G$177,Dados!$A$3:$A$177,$A9) -> 9 | M9: =SUMIFS(Dados!$H$3:$H$177,Dados!$A$3:$A$177,$A9) -> 14 | N9: =IFERROR(M9/L9,0) -> 1.5555556 | O9: =H9/3*100 -> 86.666667 | P9: =IF(L9=0,100,(1-M9/(3*L9))*100) -> 48.148148 | Q9: =K9*100 -> 71.428571 | R9: =Config!$B$4*O9+Config!$B$5*P9+Config!$B$6*Q9 -> 75.153439 | S9: =IFERROR(VLOOKUP($D9,Config!$A$12:$B$24,2,FALSE()),1) -> 0.96 | T9: =R9*S9 -> 72.147302 | U9: =G9+(3*L9-M9) -> 26 | V9: =IF($A9="","",SUMPRODUCT(($B$3:$B$27=$B9)*($T$3:$T$27>$T9))+1) -> 4 | W9: =IF($A9="","",IF($F9<Config!$B$7,"Sem amostra",IF(AND($B9>1,$V9<=Config!$B$8),"⬆ Promoção",IF(AND($B9<5,$V9>COUNTIF($B$3:$B$27,$B9)-Config!$B$8),"⬇ Rebaixamento","—")))) -> ⬇ Rebaixamento
A10: =Jogadores!A10 -> Léo | B10: =IFERROR(VLOOKUP($A10,Jogadores!$A$3:$C$120,2,FALSE()),"") -> 2 | C10: =IFERROR(VLOOKUP($B10,Config!$A$29:$C$33,2,FALSE()),"") -> RezaSpamandu | D10: =IFERROR(VLOOKUP($B10,Config!$A$29:$C$33,3,FALSE()),"") -> Champion III | E10: =IFERROR(VLOOKUP($A10,Jogadores!$A$3:$C$120,3,FALSE()),"") -> 14 | F10: =COUNTIFS(Dados!$A$3:$A$177,$A10,Dados!$E$3:$E$177,">=0") -> 7 | G10: =SUMIFS(Dados!$E$3:$E$177,Dados!$A$3:$A$177,$A10) -> 19 | H10: =IFERROR(G10/F10,0) -> 2.7142857 | I10: =IFERROR(AVERAGEIFS(Dados!$F$3:$F$177,Dados!$A$3:$A$177,$A10,Dados!$E$3:$E$177,">=0"),0) -> 95.428571 | J10: =COUNTIFS(Dados!$A$3:$A$177,$A10,Dados!$C$3:$C$177,"S",Dados!$D$3:$D$177,"N") -> 7 | K10: =IFERROR(MIN(1,F10/J10),0) -> 1 | L10: =SUMIFS(Dados!$G$3:$G$177,Dados!$A$3:$A$177,$A10) -> 10 | M10: =SUMIFS(Dados!$H$3:$H$177,Dados!$A$3:$A$177,$A10) -> 9 | N10: =IFERROR(M10/L10,0) -> 0.9 | O10: =H10/3*100 -> 90.47619 | P10: =IF(L10=0,100,(1-M10/(3*L10))*100) -> 70 | Q10: =K10*100 -> 100 | R10: =Config!$B$4*O10+Config!$B$5*P10+Config!$B$6*Q10 -> 88.761905 | S10: =IFERROR(VLOOKUP($D10,Config!$A$12:$B$24,2,FALSE()),1) -> 0.96 | T10: =R10*S10 -> 85.211429 | U10: =G10+(3*L10-M10) -> 40 | V10: =IF($A10="","",SUMPRODUCT(($B$3:$B$27=$B10)*($T$3:$T$27>$T10))+1) -> 3 | W10: =IF($A10="","",IF($F10<Config!$B$7,"Sem amostra",IF(AND($B10>1,$V10<=Config!$B$8),"⬆ Promoção",IF(AND($B10<5,$V10>COUNTIF($B$3:$B$27,$B10)-Config!$B$8),"⬇ Rebaixamento","—")))) -> —
A11: =Jogadores!A11 -> Mari | B11: =IFERROR(VLOOKUP($A11,Jogadores!$A$3:$C$120,2,FALSE()),"") -> 2 | C11: =IFERROR(VLOOKUP($B11,Config!$A$29:$C$33,2,FALSE()),"") -> RezaSpamandu | D11: =IFERROR(VLOOKUP($B11,Config!$A$29:$C$33,3,FALSE()),"") -> Champion III | E11: =IFERROR(VLOOKUP($A11,Jogadores!$A$3:$C$120,3,FALSE()),"") -> 15 | F11: =COUNTIFS(Dados!$A$3:$A$177,$A11,Dados!$E$3:$E$177,">=0") -> 6 | G11: =SUMIFS(Dados!$E$3:$E$177,Dados!$A$3:$A$177,$A11) -> 18 | H11: =IFERROR(G11/F11,0) -> 3 | I11: =IFERROR(AVERAGEIFS(Dados!$F$3:$F$177,Dados!$A$3:$A$177,$A11,Dados!$E$3:$E$177,">=0"),0) -> 98.333333 | J11: =COUNTIFS(Dados!$A$3:$A$177,$A11,Dados!$C$3:$C$177,"S",Dados!$D$3:$D$177,"N") -> 7 | K11: =IFERROR(MIN(1,F11/J11),0) -> 0.85714286 | L11: =SUMIFS(Dados!$G$3:$G$177,Dados!$A$3:$A$177,$A11) -> 11 | M11: =SUMIFS(Dados!$H$3:$H$177,Dados!$A$3:$A$177,$A11) -> 9 | N11: =IFERROR(M11/L11,0) -> 0.81818182 | O11: =H11/3*100 -> 100 | P11: =IF(L11=0,100,(1-M11/(3*L11))*100) -> 72.727273 | Q11: =K11*100 -> 85.714286 | R11: =Config!$B$4*O11+Config!$B$5*P11+Config!$B$6*Q11 -> 90.974026 | S11: =IFERROR(VLOOKUP($D11,Config!$A$12:$B$24,2,FALSE()),1) -> 0.96 | T11: =R11*S11 -> 87.335065 | U11: =G11+(3*L11-M11) -> 42 | V11: =IF($A11="","",SUMPRODUCT(($B$3:$B$27=$B11)*($T$3:$T$27>$T11))+1) -> 1 | W11: =IF($A11="","",IF($F11<Config!$B$7,"Sem amostra",IF(AND($B11>1,$V11<=Config!$B$8),"⬆ Promoção",IF(AND($B11<5,$V11>COUNTIF($B$3:$B$27,$B11)-Config!$B$8),"⬇ Rebaixamento","—")))) -> ⬆ Promoção
A12: =Jogadores!A12 -> Zé | B12: =IFERROR(VLOOKUP($A12,Jogadores!$A$3:$C$120,2,FALSE()),"") -> 2 | C12: =IFERROR(VLOOKUP($B12,Config!$A$29:$C$33,2,FALSE()),"") -> RezaSpamandu | D12: =IFERROR(VLOOKUP($B12,Config!$A$29:$C$33,3,FALSE()),"") -> Champion III | E12: =IFERROR(VLOOKUP($A12,Jogadores!$A$3:$C$120,3,FALSE()),"") -> 14 | F12: =COUNTIFS(Dados!$A$3:$A$177,$A12,Dados!$E$3:$E$177,">=0") -> 1 | G12: =SUMIFS(Dados!$E$3:$E$177,Dados!$A$3:$A$177,$A12) -> 1 | H12: =IFERROR(G12/F12,0) -> 1 | I12: =IFERROR(AVERAGEIFS(Dados!$F$3:$F$177,Dados!$A$3:$A$177,$A12,Dados!$E$3:$E$177,">=0"),0) -> 69 | J12: =COUNTIFS(Dados!$A$3:$A$177,$A12,Dados!$C$3:$C$177,"S",Dados!$D$3:$D$177,"N") -> 5 | K12: =IFERROR(MIN(1,F12/J12),0) -> 0.2 | L12: =SUMIFS(Dados!$G$3:$G$177,Dados!$A$3:$A$177,$A12) -> 10 | M12: =SUMIFS(Dados!$H$3:$H$177,Dados!$A$3:$A$177,$A12) -> 16 | N12: =IFERROR(M12/L12,0) -> 1.6 | O12: =H12/3*100 -> 33.333333 | P12: =IF(L12=0,100,(1-M12/(3*L12))*100) -> 46.666667 | Q12: =K12*100 -> 20 | R12: =Config!$B$4*O12+Config!$B$5*P12+Config!$B$6*Q12 -> 32.666667 | S12: =IFERROR(VLOOKUP($D12,Config!$A$12:$B$24,2,FALSE()),1) -> 0.96 | T12: =R12*S12 -> 31.36 | U12: =G12+(3*L12-M12) -> 15 | V12: =IF($A12="","",SUMPRODUCT(($B$3:$B$27=$B12)*($T$3:$T$27>$T12))+1) -> 5 | W12: =IF($A12="","",IF($F12<Config!$B$7,"Sem amostra",IF(AND($B12>1,$V12<=Config!$B$8),"⬆ Promoção",IF(AND($B12<5,$V12>COUNTIF($B$3:$B$27,$B12)-Config!$B$8),"⬇ Rebaixamento","—")))) -> Sem amostra
A13: =Jogadores!A13 -> Pedro | B13: =IFERROR(VLOOKUP($A13,Jogadores!$A$3:$C$120,2,FALSE()),"") -> 3 | C13: =IFERROR(VLOOKUP($B13,Config!$A$29:$C$33,2,FALSE()),"") -> ScamiReza | D13: =IFERROR(VLOOKUP($B13,Config!$A$29:$C$33,3,FALSE()),"") -> Master I | E13: =IFERROR(VLOOKUP($A13,Jogadores!$A$3:$C$120,3,FALSE()),"") -> 14 | F13: =COUNTIFS(Dados!$A$3:$A$177,$A13,Dados!$E$3:$E$177,">=0") -> 7 | G13: =SUMIFS(Dados!$E$3:$E$177,Dados!$A$3:$A$177,$A13) -> 19 | H13: =IFERROR(G13/F13,0) -> 2.7142857 | I13: =IFERROR(AVERAGEIFS(Dados!$F$3:$F$177,Dados!$A$3:$A$177,$A13,Dados!$E$3:$E$177,">=0"),0) -> 97.714286 | J13: =COUNTIFS(Dados!$A$3:$A$177,$A13,Dados!$C$3:$C$177,"S",Dados!$D$3:$D$177,"N") -> 7 | K13: =IFERROR(MIN(1,F13/J13),0) -> 1 | L13: =SUMIFS(Dados!$G$3:$G$177,Dados!$A$3:$A$177,$A13) -> 9 | M13: =SUMIFS(Dados!$H$3:$H$177,Dados!$A$3:$A$177,$A13) -> 5 | N13: =IFERROR(M13/L13,0) -> 0.55555556 | O13: =H13/3*100 -> 90.47619 | P13: =IF(L13=0,100,(1-M13/(3*L13))*100) -> 81.481481 | Q13: =K13*100 -> 100 | R13: =Config!$B$4*O13+Config!$B$5*P13+Config!$B$6*Q13 -> 91.058201 | S13: =IFERROR(VLOOKUP($D13,Config!$A$12:$B$24,2,FALSE()),1) -> 0.93 | T13: =R13*S13 -> 84.684127 | U13: =G13+(3*L13-M13) -> 41 | V13: =IF($A13="","",SUMPRODUCT(($B$3:$B$27=$B13)*($T$3:$T$27>$T13))+1) -> 2 | W13: =IF($A13="","",IF($F13<Config!$B$7,"Sem amostra",IF(AND($B13>1,$V13<=Config!$B$8),"⬆ Promoção",IF(AND($B13<5,$V13>COUNTIF($B$3:$B$27,$B13)-Config!$B$8),"⬇ Rebaixamento","—")))) -> ⬆ Promoção
A14: =Jogadores!A14 -> Nanda | B14: =IFERROR(VLOOKUP($A14,Jogadores!$A$3:$C$120,2,FALSE()),"") -> 3 | C14: =IFERROR(VLOOKUP($B14,Config!$A$29:$C$33,2,FALSE()),"") -> ScamiReza | D14: =IFERROR(VLOOKUP($B14,Config!$A$29:$C$33,3,FALSE()),"") -> Master I | E14: =IFERROR(VLOOKUP($A14,Jogadores!$A$3:$C$120,3,FALSE()),"") -> 14 | F14: =COUNTIFS(Dados!$A$3:$A$177,$A14,Dados!$E$3:$E$177,">=0") -> 5 | G14: =SUMIFS(Dados!$E$3:$E$177,Dados!$A$3:$A$177,$A14) -> 14 | H14: =IFERROR(G14/F14,0) -> 2.8 | I14: =IFERROR(AVERAGEIFS(Dados!$F$3:$F$177,Dados!$A$3:$A$177,$A14,Dados!$E$3:$E$177,">=0"),0) -> 96.6 | J14: =COUNTIFS(Dados!$A$3:$A$177,$A14,Dados!$C$3:$C$177,"S",Dados!$D$3:$D$177,"N") -> 7 | K14: =IFERROR(MIN(1,F14/J14),0) -> 0.71428571 | L14: =SUMIFS(Dados!$G$3:$G$177,Dados!$A$3:$A$177,$A14) -> 11 | M14: =SUMIFS(Dados!$H$3:$H$177,Dados!$A$3:$A$177,$A14) -> 7 | N14: =IFERROR(M14/L14,0) -> 0.63636364 | O14: =H14/3*100 -> 93.333333 | P14: =IF(L14=0,100,(1-M14/(3*L14))*100) -> 78.787879 | Q14: =K14*100 -> 71.428571 | R14: =Config!$B$4*O14+Config!$B$5*P14+Config!$B$6*Q14 -> 84.948052 | S14: =IFERROR(VLOOKUP($D14,Config!$A$12:$B$24,2,FALSE()),1) -> 0.93 | T14: =R14*S14 -> 79.001688 | U14: =G14+(3*L14-M14) -> 40 | V14: =IF($A14="","",SUMPRODUCT(($B$3:$B$27=$B14)*($T$3:$T$27>$T14))+1) -> 4 | W14: =IF($A14="","",IF($F14<Config!$B$7,"Sem amostra",IF(AND($B14>1,$V14<=Config!$B$8),"⬆ Promoção",IF(AND($B14<5,$V14>COUNTIF($B$3:$B$27,$B14)-Config!$B$8),"⬇ Rebaixamento","—")))) -> ⬇ Rebaixamento
... A27: =Jogadores!A27 -> Nino | B27: =IFERROR(VLOOKUP($A27,Jogadores!$A$3:$C$120,2,FALSE()),"") -> 5 | C27: =IFERROR(VLOOKUP($B27,Config!$A$29:$C$33,2,FALSE()),"") -> e-SpamiReza | D27: =IFERROR(VLOOKUP($B27,Config!$A$29:$C$33,3,FALSE()),"") -> Crystal I | E27: =IFERROR(VLOOKUP($A27,Jogadores!$A$3:$C$120,3,FALSE()),"") -> 11 | F27: =COUNTIFS(Dados!$A$3:$A$177,$A27,Dados!$E$3:$E$177,">=0") -> 3 | G27: =SUMIFS(Dados!$E$3:$E$177,Dados!$A$3:$A$177,$A27) -> 6 | H27: =IFERROR(G27/F27,0) -> 2 | I27: =IFERROR(AVERAGEIFS(Dados!$F$3:$F$177,Dados!$A$3:$A$177,$A27,Dados!$E$3:$E$177,">=0"),0) -> 80.666667 | J27: =COUNTIFS(Dados!$A$3:$A$177,$A27,Dados!$C$3:$C$177,"S",Dados!$D$3:$D$177,"N") -> 5 | K27: =IFERROR(MIN(1,F27/J27),0) -> 0.6 | L27: =SUMIFS(Dados!$G$3:$G$177,Dados!$A$3:$A$177,$A27) -> 10 | M27: =SUMIFS(Dados!$H$3:$H$177,Dados!$A$3:$A$177,$A27) -> 8 | N27: =IFERROR(M27/L27,0) -> 0.8 | O27: =H27/3*100 -> 66.666667 | P27: =IF(L27=0,100,(1-M27/(3*L27))*100) -> 73.333333 | Q27: =K27*100 -> 60 | R27: =Config!$B$4*O27+Config!$B$5*P27+Config!$B$6*Q27 -> 66.333333 | S27: =IFERROR(VLOOKUP($D27,Config!$A$12:$B$24,2,FALSE()),1) -> 0.83 | T27: =R27*S27 -> 55.056667 | U27: =G27+(3*L27-M27) -> 28 | V27: =IF($A27="","",SUMPRODUCT(($B$3:$B$27=$B27)*($T$3:$T$27>$T27))+1) -> 5 | W27: =IF($A27="","",IF($F27<Config!$B$7,"Sem amostra",IF(AND($B27>1,$V27<=Config!$B$8),"⬆ Promoção",IF(AND($B27<5,$V27>COUNTIF($B$3:$B$27,$B27)-Config!$B$8),"⬇ Rebaixamento","—")))) -> —
